<?xml version="1.0" encoding="UTF-8"?>
<testng-results skipped="0" failed="2" ignored="0" total="2" passed="0">
  <reporter-output>
  </reporter-output>
  <suite name="Suite" duration-ms="22264" started-at="2020-09-13T06:26:38Z" finished-at="2020-09-13T06:27:00Z">
    <groups>
    </groups>
    <test name="Test1" duration-ms="12916" started-at="2020-09-13T06:26:38Z" finished-at="2020-09-13T06:26:51Z">
      <class name="gitTest.GitTest">
        <test-method status="FAIL" signature="loginTest()[pri:0, instance:gitTest.GitTest@3f49dace]" name="loginTest" duration-ms="12859" started-at="2020-09-13T11:56:38Z" finished-at="2020-09-13T11:56:51Z">
          <exception class="java.lang.ArithmeticException">
            <message>
              <![CDATA[/ by zero]]>
            </message>
            <full-stacktrace>
              <![CDATA[java.lang.ArithmeticException: / by zeroat gitTest.GitTest.loginTest(GitTest.java:43)at sun.reflect.NativeMethodAccessorImpl.invoke0(Native Method)at sun.reflect.NativeMethodAccessorImpl.invoke(NativeMethodAccessorImpl.java:62)at sun.reflect.DelegatingMethodAccessorImpl.invoke(DelegatingMethodAccessorImpl.java:43)at java.lang.reflect.Method.invoke(Method.java:498)at org.testng.internal.MethodInvocationHelper.invokeMethod(MethodInvocationHelper.java:124)at org.testng.internal.Invoker.invokeMethod(Invoker.java:571)at org.testng.internal.Invoker.invokeTestMethod(Invoker.java:707)at org.testng.internal.Invoker.invokeTestMethods(Invoker.java:979)at org.testng.internal.TestMethodWorker.invokeTestMethods(TestMethodWorker.java:125)at org.testng.internal.TestMethodWorker.run(TestMethodWorker.java:109)at org.testng.TestRunner.privateRun(TestRunner.java:648)at org.testng.TestRunner.run(TestRunner.java:505)at org.testng.SuiteRunner.runTest(SuiteRunner.java:455)at org.testng.SuiteRunner.runSequentially(SuiteRunner.java:450)at org.testng.SuiteRunner.privateRun(SuiteRunner.java:415)at org.testng.SuiteRunner.run(SuiteRunner.java:364)at org.testng.SuiteRunnerWorker.runSuite(SuiteRunnerWorker.java:52)at org.testng.SuiteRunnerWorker.run(SuiteRunnerWorker.java:84)at org.testng.TestNG.runSuitesSequentially(TestNG.java:1187)at org.testng.TestNG.runSuitesLocally(TestNG.java:1116)at org.testng.TestNG.runSuites(TestNG.java:1028)at org.testng.TestNG.run(TestNG.java:996)at org.apache.maven.surefire.testng.TestNGExecutor.run(TestNGExecutor.java:295)at org.apache.maven.surefire.testng.TestNGXmlTestSuite.execute(TestNGXmlTestSuite.java:84)at org.apache.maven.surefire.testng.TestNGProvider.invoke(TestNGProvider.java:90)at org.apache.maven.surefire.booter.ForkedBooter.invokeProviderInSameClassLoader(ForkedBooter.java:203)at org.apache.maven.surefire.booter.ForkedBooter.runSuitesInProcess(ForkedBooter.java:155)at org.apache.maven.surefire.booter.ForkedBooter.main(ForkedBooter.java:103)]]>
            </full-stacktrace>
          </exception> <!-- java.lang.ArithmeticException -->
          <reporter-output>
          </reporter-output>
        </test-method> <!-- loginTest -->
      </class> <!-- gitTest.GitTest -->
    </test> <!-- Test1 -->
    <test name="Test" duration-ms="9284" started-at="2020-09-13T06:26:51Z" finished-at="2020-09-13T06:27:00Z">
      <class name="sampleTest.SampleTest">
        <test-method status="FAIL" signature="loginTest()[pri:0, instance:sampleTest.SampleTest@1e127982]" name="loginTest" duration-ms="9281" started-at="2020-09-13T11:56:51Z" finished-at="2020-09-13T11:57:00Z">
          <exception class="java.lang.ArithmeticException">
            <message>
              <![CDATA[/ by zero]]>
            </message>
            <full-stacktrace>
              <![CDATA[java.lang.ArithmeticException: / by zeroat sampleTest.SampleTest.loginTest(SampleTest.java:38)at sun.reflect.NativeMethodAccessorImpl.invoke0(Native Method)at sun.reflect.NativeMethodAccessorImpl.invoke(NativeMethodAccessorImpl.java:62)at sun.reflect.DelegatingMethodAccessorImpl.invoke(DelegatingMethodAccessorImpl.java:43)at java.lang.reflect.Method.invoke(Method.java:498)at org.testng.internal.MethodInvocationHelper.invokeMethod(MethodInvocationHelper.java:124)at org.testng.internal.Invoker.invokeMethod(Invoker.java:571)at org.testng.internal.Invoker.invokeTestMethod(Invoker.java:707)at org.testng.internal.Invoker.invokeTestMethods(Invoker.java:979)at org.testng.internal.TestMethodWorker.invokeTestMethods(TestMethodWorker.java:125)at org.testng.internal.TestMethodWorker.run(TestMethodWorker.java:109)at org.testng.TestRunner.privateRun(TestRunner.java:648)at org.testng.TestRunner.run(TestRunner.java:505)at org.testng.SuiteRunner.runTest(SuiteRunner.java:455)at org.testng.SuiteRunner.runSequentially(SuiteRunner.java:450)at org.testng.SuiteRunner.privateRun(SuiteRunner.java:415)at org.testng.SuiteRunner.run(SuiteRunner.java:364)at org.testng.SuiteRunnerWorker.runSuite(SuiteRunnerWorker.java:52)at org.testng.SuiteRunnerWorker.run(SuiteRunnerWorker.java:84)at org.testng.TestNG.runSuitesSequentially(TestNG.java:1187)at org.testng.TestNG.runSuitesLocally(TestNG.java:1116)at org.testng.TestNG.runSuites(TestNG.java:1028)at org.testng.TestNG.run(TestNG.java:996)at org.apache.maven.surefire.testng.TestNGExecutor.run(TestNGExecutor.java:295)at org.apache.maven.surefire.testng.TestNGXmlTestSuite.execute(TestNGXmlTestSuite.java:84)at org.apache.maven.surefire.testng.TestNGProvider.invoke(TestNGProvider.java:90)at org.apache.maven.surefire.booter.ForkedBooter.invokeProviderInSameClassLoader(ForkedBooter.java:203)at org.apache.maven.surefire.booter.ForkedBooter.runSuitesInProcess(ForkedBooter.java:155)at org.apache.maven.surefire.booter.ForkedBooter.main(ForkedBooter.java:103)]]>
            </full-stacktrace>
          </exception> <!-- java.lang.ArithmeticException -->
          <reporter-output>
          </reporter-output>
        </test-method> <!-- loginTest -->
      </class> <!-- sampleTest.SampleTest -->
    </test> <!-- Test -->
  </suite> <!-- Suite -->
</testng-results>
